Workbook
Name Date_Values: '[1]Reference Sheet'!$D$4:$D$16
Name EmployeeName: '[1]Input Sheet August 2019'!$C$7:$C$36
Name Lehmann_Thomas: #REF!
Name Lehmann_Thomas: #REF!
Name Lehmann_Thomas: #REF!
Name Lehmann_Thomas: #REF!
Name Lehmann_Thomas: #REF!
Name Lehmann_Thomas: #REF!
Name Months: '[1]Reference Sheet'!$H$5:$H$16
Name SEZ: #REF!
Name SEZ: #REF!
Name SEZ: #REF!
Name SEZ: #REF!
Name SEZ: #REF!
Name SEZ: #REF!
Name Sl_No: #REF!
Name Sl_No: #REF!
Name Sl_No: #REF!
Name Sl_No: #REF!
Name Sl_No: #REF!
Name Sl_No: #REF!

Sheet In -out register
A1: Register of In and Out register of the Gate Entry which needs to match with the FORM No. XXVI (See Rule 75) Register of Employment of Contract Labour | N1: Month | S1: 46113 | V1: Work Locaiton | Z1: Bosch Global Software Technologies Private Limited KGISL Infrastructure Private Limited - SEZ, Keeranatham Village, Saravanampatti, Coimbatore – 641035.
A2: Name and address of the Main Contractor: | E2: CBRE Inc,Building, G/F, Press Trust Of India, 4, Sansad Marg, Sansad Marg Area, New Delhi, Delhi 110001 | V2: WATER WORKS ENGINEERING #65-B, GURUSAMY NAGAR, THANNEERPANDAL, PEELAMEDU, COIMBATORE-641 004.
A3: Serial No. | B3: E Code | C3: Name of the Workman | D3: Swipe / Entry Records | E3: Daily hours of work done | AJ3: Total Hrs Woked | AK3: Number of days worked | AL3: Over Time Hours
E4: 1 | F4: 2 | G4: 3 | H4: 4 | I4: 5 | J4: 6 | K4: 7 | L4: 8 | M4: 9 | N4: 10 | O4: 11 | P4: 12 | Q4: 13 | R4: 14 | S4: 15 | T4: 16 | U4: 17 | V4: 18 | W4: 19 | X4: 20 | Y4: 21 | Z4: 22 | AA4: 23 | AB4: 24 | AC4: 25 | AD4: 26 | AE4: 27 | AF4: 28 | AG4: 29 | AH4: 30
A5: 1 | D5: In | AJ5: =SUM(F7:AI7) -> 0 | AK5: =COUNTIF(F7:AI7,">=8:00") -> 0 | AL5: =SUM(F8:V8) -> 0
D6: Out
D7: Actual Hours worked, | E7: =IF(E6<E5,E6+1-E5,E6-E5) -> 0 | F7: =IF(F6<F5,F6+1-F5,F6-F5) -> 0 | G7: =IF(G6<G5,G6+1-G5,G6-G5) -> 0 | H7: =IF(H6<H5,H6+1-H5,H6-H5) -> 0 | I7: =IF(I6<I5,I6+1-I5,I6-I5) -> 0 | J7: =IF(J6<J5,J6+1-J5,J6-J5) -> 0 | K7: =IF(K6<K5,K6+1-K5,K6-K5) -> 0 | L7: =IF(L6<L5,L6+1-L5,L6-L5) -> 0 | ... AH7: =IF(AH6<AH5,AH6+1-AH5,AH6-AH5) -> 0
D8: OT Hours | E8: =IF(E7>TIME(8,0,0),E7-TIME(8,0,0),0) -> 0 | F8: =IF(F7>TIME(8,0,0),F7-TIME(8,0,0),0) -> 0 | G8: =IF(G7>TIME(8,0,0),G7-TIME(8,0,0),0) -> 0 | H8: =IF(H7>TIME(8,0,0),H7-TIME(8,0,0),0) -> 0 | I8: =IF(I7>TIME(8,0,0),I7-TIME(8,0,0),0) -> 0 | J8: =IF(J7>TIME(8,0,0),J7-TIME(8,0,0),0) -> 0 | K8: =IF(K7>TIME(8,0,0),K7-TIME(8,0,0),0) -> 0 | L8: =IF(L7>TIME(8,0,0),L7-TIME(8,0,0),0) -> 0 | ... AH8: =IF(AH7>TIME(8,0,0),AH7-TIME(8,0,0),0) -> 0
A9: 2 | D9: In | AJ9: =SUM(F11:AI11) -> 0 | AK9: =COUNTIF(F11:AI11,">=8:00") -> 0 | AL9: =SUM(F12:V12) -> 0
D10: Out
D11: Actual Hours worked, | E11: =IF(E10<E9,E10+1-E9,E10-E9) -> 0 | F11: =IF(F10<F9,F10+1-F9,F10-F9) -> 0 | G11: =IF(G10<G9,G10+1-G9,G10-G9) -> 0 | H11: =IF(H10<H9,H10+1-H9,H10-H9) -> 0 | I11: =IF(I10<I9,I10+1-I9,I10-I9) -> 0 | J11: =IF(J10<J9,J10+1-J9,J10-J9) -> 0 | K11: =IF(K10<K9,K10+1-K9,K10-K9) -> 0 | L11: =IF(L10<L9,L10+1-L9,L10-L9) -> 0 | ... AH11: =IF(AH10<AH9,AH10+1-AH9,AH10-AH9) -> 0
D12: OT Hours | E12: =IF(E11>TIME(8,0,0),E11-TIME(8,0,0),0) -> 0 | F12: =IF(F11>TIME(8,0,0),F11-TIME(8,0,0),0) -> 0 | G12: =IF(G11>TIME(8,0,0),G11-TIME(8,0,0),0) -> 0 | H12: =IF(H11>TIME(8,0,0),H11-TIME(8,0,0),0) -> 0 | I12: =IF(I11>TIME(8,0,0),I11-TIME(8,0,0),0) -> 0 | J12: =IF(J11>TIME(8,0,0),J11-TIME(8,0,0),0) -> 0 | K12: =IF(K11>TIME(8,0,0),K11-TIME(8,0,0),0) -> 0 | L12: =IF(L11>TIME(8,0,0),L11-TIME(8,0,0),0) -> 0 | ... AH12: =IF(AH11>TIME(8,0,0),AH11-TIME(8,0,0),0) -> 0
A13: 3 | D13: In | AJ13: =SUM(F15:AI15) -> 0 | AK13: =COUNTIF(F15:AI15,">=8:00") -> 0 | AL13: =SUM(F16:V16) -> 0
D14: Out
D15: Actual Hours worked, | E15: =IF(E14<E13,E14+1-E13,E14-E13) -> 0 | F15: =IF(F14<F13,F14+1-F13,F14-F13) -> 0 | G15: =IF(G14<G13,G14+1-G13,G14-G13) -> 0 | H15: =IF(H14<H13,H14+1-H13,H14-H13) -> 0 | I15: =IF(I14<I13,I14+1-I13,I14-I13) -> 0 | J15: =IF(J14<J13,J14+1-J13,J14-J13) -> 0 | K15: =IF(K14<K13,K14+1-K13,K14-K13) -> 0 | L15: =IF(L14<L13,L14+1-L13,L14-L13) -> 0 | ... AH15: =IF(AH14<AH13,AH14+1-AH13,AH14-AH13) -> 0
D16: OT Hours | E16: =IF(E15>TIME(8,0,0),E15-TIME(8,0,0),0) -> 0 | F16: =IF(F15>TIME(8,0,0),F15-TIME(8,0,0),0) -> 0 | G16: =IF(G15>TIME(8,0,0),G15-TIME(8,0,0),0) -> 0 | H16: =IF(H15>TIME(8,0,0),H15-TIME(8,0,0),0) -> 0 | I16: =IF(I15>TIME(8,0,0),I15-TIME(8,0,0),0) -> 0 | J16: =IF(J15>TIME(8,0,0),J15-TIME(8,0,0),0) -> 0 | K16: =IF(K15>TIME(8,0,0),K15-TIME(8,0,0),0) -> 0 | L16: =IF(L15>TIME(8,0,0),L15-TIME(8,0,0),0) -> 0 | ... AH16: =IF(AH15>TIME(8,0,0),AH15-TIME(8,0,0),0) -> 0
A17: 4 | D17: In | AJ17: =SUM(F19:AI19) -> 0 | AK17: =COUNTIF(F19:AI19,">=8:00") -> 0 | AL17: =SUM(F20:V20) -> 0
D18: Out
D19: Actual Hours worked, | E19: =IF(E18<E17,E18+1-E17,E18-E17) -> 0 | F19: =IF(F18<F17,F18+1-F17,F18-F17) -> 0 | G19: =IF(G18<G17,G18+1-G17,G18-G17) -> 0 | H19: =IF(H18<H17,H18+1-H17,H18-H17) -> 0 | I19: =IF(I18<I17,I18+1-I17,I18-I17) -> 0 | J19: =IF(J18<J17,J18+1-J17,J18-J17) -> 0 | K19: =IF(K18<K17,K18+1-K17,K18-K17) -> 0 | L19: =IF(L18<L17,L18+1-L17,L18-L17) -> 0 | ... AH19: =IF(AH18<AH17,AH18+1-AH17,AH18-AH17) -> 0
D20: OT Hours | E20: =IF(E19>TIME(8,0,0),E19-TIME(8,0,0),0) -> 0 | F20: =IF(F19>TIME(8,0,0),F19-TIME(8,0,0),0) -> 0 | G20: =IF(G19>TIME(8,0,0),G19-TIME(8,0,0),0) -> 0 | H20: =IF(H19>TIME(8,0,0),H19-TIME(8,0,0),0) -> 0 | I20: =IF(I19>TIME(8,0,0),I19-TIME(8,0,0),0) -> 0 | J20: =IF(J19>TIME(8,0,0),J19-TIME(8,0,0),0) -> 0 | K20: =IF(K19>TIME(8,0,0),K19-TIME(8,0,0),0) -> 0 | L20: =IF(L19>TIME(8,0,0),L19-TIME(8,0,0),0) -> 0 | ... AH20: =IF(AH19>TIME(8,0,0),AH19-TIME(8,0,0),0) -> 0
A21: Certified that the above said employees timings were captured as per the Gate Entry of their physical presence to the Principal Employer Premises for the month of Apr 2026
I1048574: `

Sheet ESIC_EPF_Tracking sheet
B1: ESIC & EPF Remittance Supportive for the month ofApr 2026
B3: Name of the Contractor: WATER WORKS ENGINEERING
B4: Address : #65-B, GURUSAMY NAGAR, THANNEERPANDAL, PEELAMEDU, COIMBATORE-641 004
B5: Nature of Work : Operation&Maintenance (STP)
B6: Company ESIC Code No.:56001274280000999
B7: Company EPF Code No. :CBCBE3191011000
B8: Work-men Compensation Policy # : with validity : -
B9: Date of ESIC remitted : 15-05-2026
B10: Date of ESIC remitted : 15-05-2026
C12: Employee Provident Fund Particulars | G12: ESIC Particulars | K12: Remaks / Location
A13: Sl. No. | B13: Name of The Employee as per the Attendance & Wage Register | C13: UAN No. | D13: PF No. | E13: Page No | F13: Sl. No. in ECR Copy | G13: ESIC No | H13: Page No | I13: Sl. No. in ECR Copy | J13: Location
A14: 1
A15: 2
A16: 3
A17: 4
A18: 5
A19: 6
A20: 7
A21: 8

Sheet Form No.XXVI
A1: FORM No. XXVI (See Rule 75) Register of Employment of Contract Labour
A2: Name and address of the Principal Employer: | D2: Bosch Global Software Technologies Private Limited KGISL Infrastructure Private Limited - SEZ, Keeranatham Village, Saravanampatti, Coimbatore – 641035. | Q2: Name and address of the Main Contractor: | Y2: CBRE Inc,Building, G/F, Press Trust Of India, 4, Sansad Marg, Sansad Marg Area, New Delhi, Delhi 110001 | AU2: Month | AV2: April
A3: Name and Location of the work site: | D3: Bosch Global Software Technologies Private Limited KGISL Infrastructure Private Limited - SEZ, Keeranatham Village, Saravanampatti, Coimbatore – 641035. | Q3: Name and address of the Sub - Contractor: | Y3: WATER WORKS ENGINEERING #65-B, GURUSAMY NAGAR, THANNEERPANDAL, PEELAMEDU, COIMBATORE-641 004. | AU3: Year | AV3: 2026
A4: Serial No. | B4: E Code | C4: Name of the workman | D4: Age and Gender | E4: Permanent /Local address | F4: Designation (Nature of work) | G4: Father's / Husband's name | H4: Date of entry into service | I4: Daily hours of work done | AO4: Number of days worked | AP4: Holiday Days | AQ4: Holiday Working Days | AR4: Paid Leave Days | AS4: Week Off Days | AT4: Total Paid Days | AU4: Signature or Thumb impression of the workman | AV4: Date of termination of employment | AW4: Signature of Contractor / Representative
I5: 1 | J5: 2 | K5: 3 | L5: 4 | M5: 5 | N5: 6 | O5: 7 | P5: 8 | Q5: 9 | R5: 10 | S5: 11 | T5: 12 | U5: 13 | V5: 14 | W5: 15 | X5: 16 | Y5: 17 | Z5: 18 | AA5: 19 | AB5: 20 | AC5: 21 | AD5: 22 | AE5: 23 | AF5: 24 | AG5: 25 | AH5: 26 | AI5: 27 | AJ5: 28 | AK5: 29 | AL5: 30 | AN5: Total Hrs Woked
A6: -1 | B6: -2 | C6: -3 | D6: -4 | E6: -5 | F6: -6 | G6: -7 | H6: -8 | I6: -9 | AO6: -10 | AP6: -11 | AQ6: -12 | AR6: -13 | AS6: -14 | AT6: -15 | AU6: -16 | AV6: -17 | AW6: -18
A7: 1 | AN7: =SUM(I7:AM7) -> 0 | AO7: =ROUND(AN7/8,2) -> 0 | AP7: 0 | AQ7: 0 | AR7: =COUNTIF(I7:AM7,"PL")+COUNTIF(I7:AM7,"CL") -> 0 | AS7: {=SUMPRODUCT(--(TRIM(I7:AM7)="W/O"))} -> 0 | AT7: =+AO7+AP7+AR7+AS7 -> 0 | AV7: -
A8: 2 | AN8: =SUM(I8:AM8) -> 0 | AO8: =ROUND(AN8/8,2) -> 0 | AP8: 0 | AQ8: 0 | AR8: =COUNTIF(I8:AM8,"PL")+COUNTIF(I8:AM8,"CL") -> 0 | AS8: {=SUMPRODUCT(--(TRIM(I8:AM8)="W/O"))} -> 0 | AT8: =+AO8+AP8+AR8+AS8 -> 0 | AV8: -
A9: 3 | AN9: =SUM(I9:AM9) -> 0 | AO9: =ROUND(AN9/8,2) -> 0 | AP9: 0 | AQ9: 0 | AR9: =COUNTIF(I9:AM9,"PL")+COUNTIF(I9:AM9,"CL") -> 0 | AS9: {=SUMPRODUCT(--(TRIM(I9:AM9)="W/O"))} -> 0 | AT9: =+AO9+AP9+AR9+AS9 -> 0
A10: 4 | AN10: =SUM(I10:AM10) -> 0 | AO10: =ROUND(AN10/8,2) -> 0 | AP10: 1 | AQ10: 1 | AR10: =COUNTIF(I10:AM10,"PL")+COUNTIF(I10:AM10,"CL") -> 0 | AS10: {=SUMPRODUCT(--(TRIM(I10:AM10)="W/O"))} -> 0 | AT10: 6 | AV10: -
A11: 5 | AN11: =SUM(I11:AM11) -> 0 | AO11: =ROUND(AN11/8,2) -> 0 | AP11: 0 | AQ11: 0 | AR11: =COUNTIF(I11:AM11,"PL")+COUNTIF(I11:AM11,"CL") -> 0 | AS11: {=SUMPRODUCT(--(TRIM(I11:AM11)="W/O"))} -> 0 | AT11: =+AO11+AP11+AR11+AS11 -> 0
A12: 6 | AN12: =SUM(I12:AM12) -> 0 | AO12: =ROUND(AN12/8,2) -> 0 | AP12: 0 | AQ12: 0 | AR12: =COUNTIF(I12:AM12,"PL")+COUNTIF(I12:AM12,"CL") -> 0 | AS12: {=SUMPRODUCT(--(TRIM(I12:AM12)="W/O"))} -> 0 | AT12: =+AO12+AP12+AR12+AS12 -> 0
G13: Total Working hours | I13: =SUM(I9:I11) -> 0 | J13: =SUM(J9:J12) -> 0 | K13: =SUM(K9:K11) -> 0 | L13: =SUM(L9:L11) -> 0 | M13: =SUM(M9:M11) -> 0 | N13: =SUM(N9:N11) -> 0 | O13: =SUM(O9:O11) -> 0 | P13: =SUM(P9:P11) -> 0 | Q13: =SUM(Q9:Q11) -> 0 | R13: =SUM(R9:R11) -> 0 | ... Y13: =SUM(Y9:Y11) -> 0 | Z13: =SUM(Z9:Z12) -> 0 | AA13: =SUM(AA9:AA11) -> 0 | AB13: =SUM(AB9:AB11) -> 0 | AC13: =SUM(AC9:AC12) -> 0 | AD13: =SUM(AD9:AD11) -> 0 | AE13: =SUM(AE9:AE11) -> 0 | AF13: =SUM(AF9:AF12) -> 0 | AG13: =SUM(AG9:AG11) -> 0 | AH13: =SUM(AH9:AH11) -> 0 | AI13: =SUM(AI9:AI11) -> 0 | AJ13: =SUM(AJ9:AJ12) -> 0 | AK13: =SUM(AK9:AK12) -> 0 | AM13: =SUM(AM9:AM12) -> 0 | AN13: =SUM(AN9:AN11) -> 0 | AO13: =SUM(AO9:AO11) -> 0 | AP13: =SUM(AP9:AP11) -> 1 | AQ13: =SUM(AQ9:AQ11) -> 1 | AR13: =SUM(AR9:AR11) -> 0 | AS13: =SUM(AS9:AS11) -> 0 | AT13: =SUM(AT9:AT11) -> 6
G14: Average day worked in this date | I14: =I13/8 -> 0 | J14: =J13/8 -> 0 | K14: =K13/8 -> 0 | L14: =L13/8 -> 0 | M14: =M13/8 -> 0 | N14: =N13/8 -> 0 | O14: =O13/8 -> 0 | P14: =P13/8 -> 0 | ... AK14: =AK13/8 -> 0 | AM14: =AM13/8 -> 0

Sheet Form XXVII Register of Wages
A1: FORM XXVII [See Rule 78 (1) (a)] Register of Wages
A2: Name of the Establishment Principal Employer: | D2: Name of the Work Locaiton where the work is carried out : Bosch Global Software Technologies Private Limited KGISL Infrastructure Private Limited - SEZ, Keeranatham Village, Saravanampatti, Coimbatore – 641035. | V2: Name of the Contractor with address: | AC2: CBRE Inc,Building, G/F, Press Trust Of India, 4, Sansad Marg, Sansad Marg Area, New Delhi, Delhi 110001 | AJ2: Wage Period : Monthly
D3: Bosch Global Software Technologies Private Limited KGISL Infrastructure Private Limited - SEZ, Keeranatham Village, Saravanampatti, Coimbatore – 641035. | V3: Name of the Sub - Contractor with address: | AC3: WATER WORKS ENGINEERING #65-B, GURUSAMY NAGAR, THANNEERPANDAL, PEELAMEDU, COIMBATORE-641 004. | AJ3: Year : April 2026
A4: Serial Number | B4: Ecode | C4: Name of workman | D4: Sex | E4: Designation / Nature of Work | F4: Daily rated / Piece rated / Monthly rated | G4: Wage Period: Monthly | H4: Total number of days worked during the Month | I4: National & Festival Holidays : | J4: Daily rate of wages / piece rate | K4: Overtime Hrs | L4: Over time Calculations | N4: Wages Per month declared for 26 days | S4: Wages Earned | AC4: Gross Wages | AD4: Deductions | AJ4: Signature with date or Thumb Impression/Cheque No. and Date in case of Payment through Bank/Advice of the Bank to be appended | AK4: Total unpaid amounts accumulated
L5: Over time Per hour | M5: Over time Double Wages | N5: Basic Per month | O5: DA Per month | P5: HRA per month | Q5: Med Allowances per month | R5: Conv. Allowances per month | S5: Basic Wages | T5: Dearness allowance | U5: HRA | V5: Medical Allowance | W5: Conv. Allowance | X5: NFH Wages | Y5: Overtime earned | Z5: Leave wages including cash in lieu of kinds | AA5: Bonus Earned | AB5: Arrear | AD5: Provident Fund | AE5: ESI | AF5: Other Deductions (LWF) (indicate nature) | AG5: Fines (if any)/P.TAX | AH5: Total Deductions | AI5: Net amount paid & Take Home Salary
A6: -1 | C6: -2 | D6: -3 | E6: -4 | F6: -5 | G6: -6 | H6: -7 | I6: -8 | J6: -9 | K6: -10 | S6: -11 | T6: -12 | V6: -13 | Y6: -14 | Z6: -15 | AC6: -16 | AD6: -17 | AE6: -18 | AF6: -19 | AG6: -20 | AH6: -21 | AI6: -22 | AJ6: -23 | AK6: -24
A7: 1 | B7: C-0065 | F7: =SUM(N7:R7) -> 19007 | G7: Monthly | H7: ='Form No.XXVI'!AO7 -> 0 | I7: - | J7: =F7/28 -> 678.82143 | L7: =(F7/26)/8 -> 91.379808 | M7: =(K7*L7)*2 -> 0 | N7: 6829 | O7: 7313 | P7: 4865 | S7: 4728 | T7: 5091 | U7: 3340 | Y7: =+M7 -> 0 | Z7: - | AA7: - | AB7: - | AC7: =+X7+U7+T7+S7+Y7 -> 13159 | AD7: =IF(ROUNDUP((+AC7-U7-Y7)*12%,0)>1800,1800,(ROUNDUP((+AC7-U7-Y7)*12%,0))) -> 1179 | AE7: =IF(ROUNDUP(AC7*0.75%,0)>158,158,(ROUNDUP(AC7*0.75%,0))) -> 99 | AH7: =SUM(AD7:AG7) + SUM(V7:W7) -> 1278 | AI7: =AC7-AH7 -> 11881 | AK7: Nil
A8: 2 | B8: C-0069 | F8: =SUM(N8:R8) -> 16991 | G8: Monthly | H8: ='Form No.XXVI'!AO8 -> 0 | I8: - | J8: =F8/28 -> 606.82143 | K8: 0 | L8: =(F8/26)/8 -> 81.6875 | M8: =(K8*L8)*2 -> 0 | N8: 6829 | O8: 7313 | P8: 2849 | S8: 4202 | T8: 4525 | U8: 1729 | Y8: =+M8 -> 0 | Z8: - | AA8: - | AB8: - | AC8: =+X8+U8+T8+S8+Y8 -> 10456 | AD8: =IF(ROUNDUP((+AC8-U8-Y8)*12%,0)>1800,1800,(ROUNDUP((+AC8-U8-Y8)*12%,0))) -> 1048 | AE8: =IF(ROUNDUP(AC8*0.75%,0)>158,158,(ROUNDUP(AC8*0.75%,0))) -> 79 | AH8: =SUM(AD8:AG8) + SUM(V8:W8) -> 1127 | AI8: =AC8-AH8 -> 9329 | AK8: Nil
A9: 3 | B9: C-0076 | F9: =SUM(N9:R9) -> 16991 | G9: Monthly | H9: ='Form No.XXVI'!AO9 -> 0 | I9: - | J9: =F9/28 -> 606.82143 | K9: 0 | L9: =(F9/26)/8 -> 81.6875 | M9: =(K9*L9)*2 -> 0 | N9: 6829 | O9: 7313 | P9: 2849 | S9: 4202 | T9: 4525 | U9: 1729 | Y9: =+M9 -> 0 | Z9: - | AA9: - | AB9: - | AC9: =+X9+U9+T9+S9+Y9 -> 10456 | AD9: =IF(ROUNDUP((+AC9-U9-Y9)*12%,0)>1800,1800,(ROUNDUP((+AC9-U9-Y9)*12%,0))) -> 1048 | AE9: =IF(ROUNDUP(AC9*0.75%,0)>158,158,(ROUNDUP(AC9*0.75%,0))) -> 79 | AH9: =SUM(AD9:AG9) + SUM(V9:W9) -> 1127 | AI9: =AC9-AH9 -> 9329 | AK9: Nil
A10: 4 | B10: C-0077 | F10: =SUM(N10:R10) -> 16991 | G10: Monthly | H10: ='Form No.XXVI'!AO10 -> 0 | I10: - | J10: =F10/28 -> 606.82143 | K10: 0 | L10: =(F10/26)/8 -> 81.6875 | M10: =(K10*L10)*2 -> 0 | N10: 6829 | O10: 7313 | P10: 2849 | S10: 2626.5385 | T10: 2812.6923 | U10: 1095.7692 | Y10: =+M10 -> 0 | Z10: - | AA10: - | AB10: - | AC10: =+X10+U10+T10+S10+Y10 -> 6535 | AD10: =IF(ROUNDUP((+AC10-U10-Y10)*12%,0)>1800,1800,(ROUNDUP((+AC10-U10-Y10)*12%,0))) -> 653 | AE10: =IF(ROUNDUP(AC10*0.75%,0)>158,158,(ROUNDUP(AC10*0.75%,0))) -> 50 | AH10: =SUM(AD10:AG10) + SUM(V10:W10) -> 703 | AI10: =AC10-AH10 -> 5832 | AK10: Nil
A11: 5 | B11: C-0078 | F11: =SUM(N11:R11) -> 16991 | G11: Monthly | H11: ='Form No.XXVI'!AO11 -> 0 | I11: - | J11: =F11/28 -> 606.82143 | K11: 0 | L11: =(F11/26)/8 -> 81.6875 | M11: =(K11*L11)*2 -> 0 | N11: 6829 | O11: 7313 | P11: 2849 | S11: 1050.6154 | T11: 1125.0769 | U11: 438.30769 | Y11: =+M11 -> 0 | Z11: - | AA11: - | AB11: - | AC11: =+X11+U11+T11+S11+Y11 -> 2614 | AD11: =IF(ROUNDUP((+AC11-U11-Y11)*12%,0)>1800,1800,(ROUNDUP((+AC11-U11-Y11)*12%,0))) -> 262 | AE11: =IF(ROUNDUP(AC11*0.75%,0)>158,158,(ROUNDUP(AC11*0.75%,0))) -> 20 | AH11: =SUM(AD11:AG11) + SUM(V11:W11) -> 282 | AI11: =AC11-AH11 -> 2332 | AK11: Nil
A12: 6 | B12: C-0079 | F12: =SUM(N12:R12) -> 16991 | G12: Monthly | H12: ='Form No.XXVI'!AO12 -> 0 | I12: - | J12: =F12/28 -> 606.82143 | K12: 0 | L12: =(F12/26)/8 -> 81.6875 | M12: =(K12*L12)*2 -> 0 | N12: 6829 | O12: 7313 | P12: 2849 | S12: 1313.2692 | T12: 1406.3462 | U12: 547.88462 | Y12: =+M12 -> 0 | Z12: - | AA12: - | AB12: - | AC12: =+X12+U12+T12+S12+Y12 -> 3267.5 | AD12: =IF(ROUNDUP((+AC12-U12-Y12)*12%,0)>1800,1800,(ROUNDUP((+AC12-U12-Y12)*12%,0))) -> 327 | AE12: =IF(ROUNDUP(AC12*0.75%,0)>158,158,(ROUNDUP(AC12*0.75%,0))) -> 25 | AH12: =SUM(AD12:AG12) + SUM(V12:W12) -> 352 | AI12: =AC12-AH12 -> 2915.5 | AK12: Nil
M13: =SUM(M7:M9) -> 0 | R13: Total | S13: =SUM(S7:S12) -> 18122.423 | T13: =SUM(T7:T12) -> 19485.115 | U13: =SUM(U7:U12) -> 8879.9615 | V13: =SUM(V7:V9) -> 0 | W13: =SUM(W7:W9) -> 0 | X13: =SUM(X7:X9) -> 0 | Y13: =SUM(Y7:Y9) -> 0 | Z13: =SUM(Z7:Z12) -> 0 | AA13: =SUM(AA7:AA12) -> 0 | AB13: =SUM(AB7:AB12) -> 0 | AC13: =SUM(AC7:AC12) -> 46487.5 | AD13: =SUM(AD7:AD12) -> 4517 | AE13: =SUM(AE7:AE12) -> 352 | AF13: =SUM(AF7:AF12) -> 0 | AG13: =SUM(AG7:AG12) -> 0 | ... AI13: =SUM(AI7:AI12) -> 41618.5 | AK13: =SUM(AK7:AK9) -> 0
A15: Certified that the wages have been paid to all the workers employed for the month of Mar 2026 for the week ending / for the F.N ending on 30-04-2026

Sheet Form XXVIII Wage Slip
B2: FORM NO.XXVIII
B3: (See Rule 78 (1)(b) of Tamil Nadu Contract labour Act (Regulation and Abolition) Rules, 1975)
C5: WAGE SLIP | H5: Date: 05.05.2026
B7: 1. Name and Address of the Establishment: | E7: WATER WORKS ENGINEERING #65-B, GURUSAMY NAGAR, THANNEERPANDAL, PEELAMEDU, COIMBATORE-641 004.
B10: 2. Name of Employee: | D10: Prakash
B11: 3. Father's/Husband's Name: | D11: Annadurai | F11: 4. Designation: | H11: Operator
B12: 5. Date of Entry into Service: | D12: 01.03.2024 | F12: 6. Wage Period: 01.04.2026 to 30.04.2026
B14: 8.Wages Earned
B15: Particulars | D15: Rs. | F15: =B15 -> Particulars | H15: Rs.
B16: (a) Basic: | D16: ='Form XXVII Register of Wages'!S7 -> 4728 | G16: Gross Wages: | H16: =D26 -> 13159
B17: (b) D.A.: | D17: ='Form XXVII Register of Wages'!T7 -> 5091 | F17: Deductions: | G17: Rs.
B18: (c) H.R.A: | D18: ='Form XXVII Register of Wages'!U7 -> 3340 | F18: (i) E.P.F: | G18: ='Form XXVII Register of Wages'!AD7 -> 1179
B19: (d) Conv. Allowances | D19: - | F19: (ii) E.S.I: | G19: ='Form XXVII Register of Wages'!AE7 -> 99
B20: (e) Med. Allowances | D20: - | F20: (iii) Prof. Tax | G20: -
B21: (f) Others | D21: - | F21: (iv) Advances | G21: ='Form XXVII Register of Wages'!AG7 -> 0
B22: (g) Others / Arrear / EL | D22: - | F22: (v) damages: | G22: -
B23: (h) National & Festiaval Wages | D23: ='Form XXVII Register of Wages'!X7 -> 0 | F23: (vi) LWF | G23: -
B24: (i) Over Time | D24: =+'Form XXVII Register of Wages'!Y7 -> 0 | F24: Total | G24: =SUM(G18:G23) -> 1278 | H24: =G24 -> 1278
B25: Others | D25: -
B26: (g) Gross Wages: | D26: =SUM(D16:D25) -> 13159 | G26: Net Amount Paid | H26: =D26-G24 -> 11881
B32: Authorised Signatory | F32: Signature or Thumb Impression of Workmen
B37: FORM NO.XXVIII
B38: (See Rule 78 (1)(b) of Tamil Nadu Contract labour Act (Regulation and Abolition) Rules, 1975)
C40: WAGE SLIP | H40: =+H5 -> Date: 05.05.2026
B42: 1. Name and Address of the Establishment: | E42: WATER WORKS ENGINEERING #65-B, GURUSAMY NAGAR, THANNEERPANDAL, PEELAMEDU, COIMBATORE-641 004.
B45: 2. Name of Employee: | D45: Poovarasan
B46: 3. Father's/Husband's Name: | D46: Jai Sankar | F46: 4. Designation: | H46: Operator
B47: 5. Date of Entry into Service: | D47: 09.12.2024 | F47: =+F12 -> 6. Wage Period: 01.04.2026 to 30.04.2026
B49: 8.Wages Earned
B50: Particulars | D50: Rs. | F50: =B50 -> Particulars | H50: Rs.
B51: (a) Basic: | D51: ='Form XXVII Register of Wages'!S8 -> 4202 | G51: Gross Wages: | H51: =D61 -> 10456
B52: (b) D.A.: | D52: ='Form XXVII Register of Wages'!T8 -> 4525 | F52: Deductions: | G52: Rs.
B53: (c) H.R.A: | D53: ='Form XXVII Register of Wages'!U8 -> 1729 | F53: (i) E.P.F: | G53: ='Form XXVII Register of Wages'!AD8 -> 1048
B54: (d) Conv. Allowances | D54: - | F54: (ii) E.S.I: | G54: ='Form XXVII Register of Wages'!AE8 -> 79
B55: (e) Med. Allowances | D55: - | F55: (iii) Prof. Tax | G55: -
B56: (f) Others | D56: - | F56: (iv) Advances | G56: =+'Form XXVII Register of Wages'!AG8 -> 0
B57: (g) Others / Arrear / EL | D57: - | F57: (v) damages: | G57: -
B58: (h) National & Festiaval Wages | D58: ='Form XXVII Register of Wages'!X8 -> 0 | F58: (vi) LWF | G58: -
B59: (i) Over Time | D59: ='Form XXVII Register of Wages'!Y8 -> 0 | F59: Total | G59: =SUM(G53:G58) -> 1127 | H59: =G59 -> 1127
B60: Others | D60: -
...

Sheet Deduction
A1: Form No XXIX [See Rule 78(1)(d)]
A2: REGISTER OF ADVANCES, DEDUCTIONS FOR DAMAGE OR LOSS AND FINES
A3: Name and address of the Establishment Principal Employeer | D3: Bosch Global Software Technologies Private Limited KGISL Infrastructure Private Limited - SEZ, Keeranatham Village, Saravanampatti, Coimbatore – 641035. | O3: Month | Q3: April | R3: Year | T3: 2026
A4: Name and Address of the Contractor | D4: WATER WORKS ENGINEERING #65-B, GURUSAMY NAGAR, THANNEERPANDAL, PEELAMEDU, COIMBATORE-641 004. | F4: Advance Paid | J4: Deductions for Damage / Loss | O4: Fines
A5: S.No | B5: Emp Code | C5: Name of the Workman | D5: Father's/Husband's Name | E5: Designation | F5: Date of Payment | G5: Amount Paid | H5: No.of.Installments to be recovered | I5: Date on which recovery completed | J5: Damage/Loss caused | K5: Date of Showcause Notice | L5: Total Amount of deduction Imposed | M5: No.of.Installments to be recovered | N5: Date on which Deduction Completed | O5: Act or Omission | P5: Date of show Cause Notice | Q5: Amount of Fine Imposed | R5: Date on which Fine recovery Completed | S5: Signature or Thumb Impression of the Workman | T5: Remarks
A6: (1) | C6: (2) | D6: (3) | E6: (5) | F6: (6) | G6: (7) | H6: (8) | I6: (9) | J6: (10) | K6: (11) | L6: (12) | M6: (13) | N6: (14) | O6: (15) | P6: (16) | Q6: (17) | R6: (18) | S6: (19) | T6: (20)
A7: 1 | F7: NIL | G7: NIL | H7: NIL | I7: NIL | J7: NIL | K7: NIL | L7: NIL | M7: NIL | N7: NIL | O7: NIL | P7: NIL | Q7: NIL | R7: NIL
A8: =+A7+1 -> 2 | F8: NIL | G8: NIL | H8: NIL | I8: NIL | J8: NIL | K8: NIL | L8: NIL | M8: NIL | N8: NIL | O8: NIL | P8: NIL | Q8: NIL | R8: NIL
A9: =A8+1 -> 3 | F9: NIL | G9: NIL | H9: NIL | I9: NIL | J9: NIL | K9: NIL | L9: NIL | M9: NIL | N9: NIL | O9: NIL | P9: NIL | Q9: NIL | R9: NIL
A10: =+A9+1 -> 4 | F10: NIL | G10: NIL | H10: NIL | I10: NIL | J10: NIL | K10: NIL | L10: NIL | M10: NIL | N10: NIL | O10: NIL | P10: NIL | Q10: NIL | R10: NIL
A11: =+A10+1 -> 5 | F11: NIL | G11: NIL | H11: NIL | I11: NIL | J11: NIL | K11: NIL | L11: NIL | M11: NIL | N11: NIL | O11: NIL | P11: NIL | Q11: NIL | R11: NIL
A12: =+A11+1 -> 6 | F12: NIL | G12: NIL | H12: NIL | I12: NIL | J12: NIL | K12: NIL | L12: NIL | M12: NIL | N12: NIL | O12: NIL | P12: NIL | Q12: NIL | R12: NIL

Sheet Form B Consolidated Wages
B4: FORM B (See Rule 29 of The Tamil Nadu Labour Welfare Fund Rules, 1973) REGISTER OF CONSOLIDATED WAGES
B5: Name of the Establishment: Water Works Engineering
B6: Month | C6: Total Number of Employees | D6: Total Emoluments payable during the month including Baisc wages DA, OT, Bonus | E6: Deductions | J6: Amount Actually Paid during the month | K6: Balance Due to Employees
E7: EPF | F7: ESI | G7: Advance or Fines | H7: Others(PT) | I7: LWF
B8: 46023 | C8: 4 | D8: 70213 | E8: 6054 | F8: 518 | J8: =+D8-E8-F8 -> 63641 | K8: -
B9: 46054 | C9: 4 | D9: 65134.308 | E9: 5876 | F9: 490 | J9: =+D9-E9-F9 -> 58768.308 | K9: -
B10: 46082 | C10: 4 | D10: 71288 | E10: 6922 | F10: 537 | J10: =+D10-E10-F10 -> 63829 | K10: -
B11: 46113 | C11: 7 | D11: 48775.25 | E11: 3275 | F11: 257 | J11: 45243.25 | K11: -
B12: 46143 | K12: -
B13: 46174 | K13: -
B14: 46204 | K14: -
B15: 46235 | K15: -
B16: 46266 | K16: -
B17: 46296 | K17: -
B18: 46327 | K18: -
B19: 46357 | K19: -

Sheet Form D Equal Wages Register
A1: FORM D [Rule 6 of The Equal Renumeration Rules 1976 (25 of 1976)] BOOK OF EQUAL RENUMERATION
A4: Name of the Establishment with full address: WATER WORKS ENGINEERING #65-B, GURUSAMY NAGAR, THANNEERPANDAL, PEELAMEDU, COIMBATORE-641 004. | F4: Total No. of Men Workers Employed | J4: 4
F5: Total No. of Women Workers Employed | J5: 0
F6: Total No. of Workers Employed | J6: =SUM(J4:J5) -> 4
A7: Month: Mar 2026
A8: Category of Workers (1) | B8: Brief Description of Work (2) | C8: Number of Employees | E8: Rate of Renumeration Paid (5) | F8: Components of Renumeration | J8: Money value of concessional commodities (10)
C9: Male (3) | D9: Female (4) | F9: Basic Wages or Salary (6) | G9: Dearness Allowance (7) | H9: House Rent Allowance (8) | I9: Others (9)
A10: Skilled | B10: STP -Operator | C10: 1 | D10: Nill | E10: 19007 | F10: 6829 | G10: 7313 | H10: =+E10-F10-G10 -> 4865 | I10: Nil | J10: Nil
A11: Semi Skilled | B11: STP -Operator | C11: 3 | D11: Nill | E11: 16991 | F11: 6829 | G11: 7313 | H11: =+E11-F11-G11 -> 2849 | I11: Nil | J11: Nil

Sheet Form VI
A1: FormNo.VI (See sub-rule (1) of rule 7
A2: Register of National and Festival Holidays - 2026
A3: Name and address of the Contractor: | E3: WATER WORKS ENGINEERING #65-B, GURUSAMY NAGAR, THANNEERPANDAL, PEELAMEDU, COIMBATORE-641 004.
A4: Name and address of the Principal Employer Name and Location of the work site: | E4: Bosch Global Software Technologies Private Limited KGISL Infrastructure Private Limited - SEZ, Keeranatham Village, Saravanampatti, Coimbatore – 641035.
A5: Seril number | B5: Name of the Employe | C5: Ticket No or Father;s Name | D5: Date of Joining | E5: Days,dated and months of the year on which National and Festiival Holidays are allowed under section 3 of the Tamil Nadu Industrail establishment (National and Festival Holidays) Act,1958 (Tamil Nadu Act XXXIII of 1958)
E6: 1 | F6: 2 | G6: 3 | H6: 4 | I6: 5 | J6: 6 | K6: 7 | L6: 8 | M6: 9 | N6: 10 | P6: Remarks / Left Date
E7: 01.01.2026 New Year | F7: 15.01.2026 Pongal | G7: 26.01.2025 | O7: Substitute Holiday
A8: 1 | B8: PRAKASH ANNADURAI | C8: Annadurai | D8: 01.03.2024 | E8: H | F8: H | G8: H | P8: Left
A9: 2 | B9: POOVARASAN JAISANKAR | C9: Jai Sankar | D9: 09.12.2024 | E9: H | F9: H | G9: H | P9: Left
A10: =A9+1 -> 3 | B10: VIGNESH SELVAM | C10: Selvam | D10: 04.02.2026 | P10: Left
B14: To be marked as follow:
B16: H' for holidays allowed
B17: W/D' for Work On Double Wages
B18: W/H' for Work with Substituted Holiday
B19: N/E' if not Eligible for the Wages

Sheet Form C Register of Unpaid
A1: The Tamilnadu Labour Welfare Fund Rules, 1973 FORM C (See Rule 29) REGISTER FOR FINES AND UNPAID ACCUMULATIONS
A4: Name of the Establishment with full address: WATER WORKS ENGINEERING #65-B, GURUSAMY NAGAR, THANNEERPANDAL, PEELAMEDU, COIMBATORE-641 004.
A7: Register for fines and unpaid accumulations for the Year: 2026
A8: Details of fines and unpaid accumulations (1) | B8: Quarter Ending 31st Mar. (2) | C8: Quarter Ending 30th Jun. (3) | D8: Quarter Ending 30th Sep. (4) | E8: Quarter Ending 31st Dec. (5)
A10: 1. Total Realisations under fines | B10: Nil
A11: 2. Total amount of accumulations being unpaid | B11: Nil
A12: i) Basic Wages | B12: Nil
A13: ii) Dearness allowance and other allowances | B13: Nil
A14: iii) Overtime | B14: Nil
A15: iv) Bonus | B15: Nil
A16: v) Gratuity | B16: Nil
A17: vi) Any other item of unpaid accumulations | B17: Nil
A18: 3. Deductions under standing orders | B18: Nil
A19: 4. Deductions under Payment of Wages Act | B19: Nil
